Workbook

Sheet Data
A1: Rk | B1: Team | C1: xGF | D1: xGA | E1: PTS% | F1: aGF | G1: aGA | H1: PDO | I1: S | J1: SA | K1: GF−xGF | L1: GA−xGA | M1: xGDiff | N1: Net Luck | O1: Gdiff | P1: Sdiff | Q1: PyThagWin% | R1: Pred PTS% | S1: XGDiffPythag | T1: XGDiffPts% | U1: Residual | V1: Pythag Residual | W1: Xpythag R | X1: XGDiff R | Y1: Py - Xpy | Z1: Std | AA1: League Average
A2: 1 | B2: Colorado Avalanche* | C2: 202.7 | D2: 152.2 | E2: =0.728*100 -> 72.8 | F2: 211 | G2: 126 | H2: 101.7 | I2: 2661 | J2: 2060 | K2: =F2-C2 -> 8.3 | L2: =G2-D2 -> -26.2 | M2: =C2-D2 -> 50.5 | N2: =K2-L2 -> 34.5 | O2: =F2-G2 -> 85 | P2: =I2-J2 -> 601 | Q2: =Table1[[#This Row],[aGF]]^2/(Table1[[#This Row],[aGF]]^2+Table1[[#This Row],[aGA]]^2)*100 -> 73.713926 | R2: =INTERCEPT($E$2:$E$33,$N$2:$N$33)+SLOPE($E$2:$E$33,$N$2:$N$33)*N2 -> 61.917776 | S2: =Table1[[#This Row],[xGF]]^2/(Table1[[#This Row],[xGF]]^2+Table1[[#This Row],[xGA]]^2)*100 -> 63.94697 | T2: =INTERCEPT($E$2:$E$33,$M$2:$M$33)+SLOPE($E$2:$E$33,$M$2:$M$33)*M2 -> 68.413818 | U2: =E2-R2 -> 10.882224 | V2: =Table1[[#This Row],[PTS%]]-Table1[[#This Row],[PyThagWin%]] -> -0.91392619 | W2: =Table1[[#This Row],[PTS%]]-Table1[[#This Row],[XGDiffPythag]] -> 8.8530305 | X2: =Table1[[#This Row],[PTS%]]-Table1[[#This Row],[XGDiffPts%]] -> 4.3861821 | Y2: =Table1[[#This Row],[PyThagWin%]]-Table1[[#This Row],[XGDiffPythag]] -> 9.7669566 | Z2: =ABS(Y2)/Q2 -> 0.13249812 | AA2: xGF | AB2: =AVERAGE(A:A) -> 16.5
A3: 2 | B3: Carolina Hurricanes | C3: 196.4 | D3: 159.3 | E3: =100*0.688 -> 68.8 | F3: 181 | G3: 159 | H3: 98.4 | I3: 2591 | J3: 1908 | K3: =F3-C3 -> -15.4 | L3: =G3-D3 -> -0.3 | M3: =C3-D3 -> 37.1 | N3: =K3-L3 -> -15.1 | O3: =F3-G3 -> 22 | P3: =I3-J3 -> 683 | Q3: =Table1[[#This Row],[aGF]]^2/(Table1[[#This Row],[aGF]]^2+Table1[[#This Row],[aGA]]^2)*100 -> 56.44361 | R3: =INTERCEPT($E$2:$E$33,$N$2:$N$33)+SLOPE($E$2:$E$33,$N$2:$N$33)*N3 -> 53.803793 | S3: =Table1[[#This Row],[xGF]]^2/(Table1[[#This Row],[xGF]]^2+Table1[[#This Row],[xGA]]^2)*100 -> 60.317892 | T3: =INTERCEPT($E$2:$E$33,$M$2:$M$33)+SLOPE($E$2:$E$33,$M$2:$M$33)*M3 -> 65.193223 | U3: =E3-R3 -> 14.996207 | V3: =Table1[[#This Row],[PTS%]]-Table1[[#This Row],[PyThagWin%]] -> 12.35639 | W3: =Table1[[#This Row],[PTS%]]-Table1[[#This Row],[XGDiffPythag]] -> 8.4821083 | X3: =Table1[[#This Row],[PTS%]]-Table1[[#This Row],[XGDiffPts%]] -> 3.6067767 | Y3: =Table1[[#This Row],[PyThagWin%]]-Table1[[#This Row],[XGDiffPythag]] -> -3.8742819 | Z3: =ABS(Y3)/Q3 -> 0.068639868 | AA3: xGA | AB3: =AVERAGE(D2:D33) -> 169.45
A4: 3 | B4: Dallas Stars* | C4: 163.4 | D4: 152 | E4: =100*0.675 -> 67.5 | F4: 163 | G4: 132 | H4: 102.1 | I4: 2014 | J4: 2094 | K4: =F4-C4 -> -0.4 | L4: =G4-D4 -> -20 | M4: =C4-D4 -> 11.4 | N4: =K4-L4 -> 19.6 | O4: =F4-G4 -> 31 | P4: =I4-J4 -> -80 | Q4: =Table1[[#This Row],[aGF]]^2/(Table1[[#This Row],[aGF]]^2+Table1[[#This Row],[aGA]]^2)*100 -> 60.393699 | R4: =INTERCEPT($E$2:$E$33,$N$2:$N$33)+SLOPE($E$2:$E$33,$N$2:$N$33)*N4 -> 59.480309 | S4: =Table1[[#This Row],[xGF]]^2/(Table1[[#This Row],[xGF]]^2+Table1[[#This Row],[xGA]]^2)*100 -> 53.609742 | T4: =INTERCEPT($E$2:$E$33,$M$2:$M$33)+SLOPE($E$2:$E$33,$M$2:$M$33)*M4 -> 59.016411 | U4: =E4-R4 -> 8.0196907 | V4: =Table1[[#This Row],[PTS%]]-Table1[[#This Row],[PyThagWin%]] -> 7.106301 | W4: =Table1[[#This Row],[PTS%]]-Table1[[#This Row],[XGDiffPythag]] -> 13.890258 | X4: =Table1[[#This Row],[PTS%]]-Table1[[#This Row],[XGDiffPts%]] -> 8.4835889 | Y4: =Table1[[#This Row],[PyThagWin%]]-Table1[[#This Row],[XGDiffPythag]] -> 6.783957 | Z4: =ABS(Y4)/Q4 -> 0.11232889 | AA4: PTS% | AB4: =AVERAGE(C:C) -> 169.44375
A5: 4 | B5: Buffalo Sabres | C5: 172 | D5: 179.7 | E5: =100*0.663 -> 66.3 | F5: 186 | G5: 154 | H5: 101.5 | I5: 2257 | J5: 2337 | K5: =F5-C5 -> 14 | L5: =G5-D5 -> -25.7 | M5: =C5-D5 -> -7.7 | N5: =K5-L5 -> 39.7 | O5: =F5-G5 -> 32 | P5: =I5-J5 -> -80 | Q5: =Table1[[#This Row],[aGF]]^2/(Table1[[#This Row],[aGF]]^2+Table1[[#This Row],[aGA]]^2)*100 -> 59.329126 | R5: =INTERCEPT($E$2:$E$33,$N$2:$N$33)+SLOPE($E$2:$E$33,$N$2:$N$33)*N5 -> 62.768435 | S5: =Table1[[#This Row],[xGF]]^2/(Table1[[#This Row],[xGF]]^2+Table1[[#This Row],[xGA]]^2)*100 -> 47.811683 | T5: =INTERCEPT($E$2:$E$33,$M$2:$M$33)+SLOPE($E$2:$E$33,$M$2:$M$33)*M5 -> 54.425862 | U5: =E5-R5 -> 3.5315647 | V5: =Table1[[#This Row],[PTS%]]-Table1[[#This Row],[PyThagWin%]] -> 6.9708739 | W5: =Table1[[#This Row],[PTS%]]-Table1[[#This Row],[XGDiffPythag]] -> 18.488317 | X5: =Table1[[#This Row],[PTS%]]-Table1[[#This Row],[XGDiffPts%]] -> 11.874138 | Y5: =Table1[[#This Row],[PyThagWin%]]-Table1[[#This Row],[XGDiffPythag]] -> 11.517443 | Z5: =ABS(Y5)/Q5 -> 0.19412797 | AA5: GF | AB5: =AVERAGE(D:D) -> 169.45
A6: 5 | B6: Montreal Canadiens | C6: 166.7 | D6: 168.4 | E6: =100*0.654 -> 65.4 | F6: 182 | G6: 158 | H6: 101.6 | I6: 2127 | J6: 2256 | K6: =F6-C6 -> 15.3 | L6: =G6-D6 -> -10.4 | M6: =C6-D6 -> -1.7 | N6: =K6-L6 -> 25.7 | O6: =F6-G6 -> 24 | P6: =I6-J6 -> -129 | Q6: =Table1[[#This Row],[aGF]]^2/(Table1[[#This Row],[aGF]]^2+Table1[[#This Row],[aGA]]^2)*100 -> 57.023826 | R6: =INTERCEPT($E$2:$E$33,$N$2:$N$33)+SLOPE($E$2:$E$33,$N$2:$N$33)*N6 -> 60.478198 | S6: =Table1[[#This Row],[xGF]]^2/(Table1[[#This Row],[xGF]]^2+Table1[[#This Row],[xGA]]^2)*100 -> 49.492702 | T6: =INTERCEPT($E$2:$E$33,$M$2:$M$33)+SLOPE($E$2:$E$33,$M$2:$M$33)*M6 -> 55.867919 | U6: =E6-R6 -> 4.9218017 | V6: =Table1[[#This Row],[PTS%]]-Table1[[#This Row],[PyThagWin%]] -> 8.3761741 | W6: =Table1[[#This Row],[PTS%]]-Table1[[#This Row],[XGDiffPythag]] -> 15.907298 | X6: =Table1[[#This Row],[PTS%]]-Table1[[#This Row],[XGDiffPts%]] -> 9.5320808 | Y6: =Table1[[#This Row],[PyThagWin%]]-Table1[[#This Row],[XGDiffPythag]] -> 7.5311241 | Z6: =ABS(Y6)/Q6 -> 0.13206978 | AA6: GA | AB6: =AVERAGE(E:E) -> 56.275
A7: 6 | B7: Tampa Bay Lightning | C7: 179.3 | D7: 160.3 | E7: =100*0.65 -> 65 | F7: 190 | G7: 146 | H7: 101.7 | I7: 2252 | J7: 2137 | K7: =F7-C7 -> 10.7 | L7: =G7-D7 -> -14.3 | M7: =C7-D7 -> 19 | N7: =K7-L7 -> 25 | O7: =F7-G7 -> 44 | P7: =I7-J7 -> 115 | Q7: =Table1[[#This Row],[aGF]]^2/(Table1[[#This Row],[aGF]]^2+Table1[[#This Row],[aGA]]^2)*100 -> 62.87446 | R7: =INTERCEPT($E$2:$E$33,$N$2:$N$33)+SLOPE($E$2:$E$33,$N$2:$N$33)*N7 -> 60.363686 | S7: =Table1[[#This Row],[xGF]]^2/(Table1[[#This Row],[xGF]]^2+Table1[[#This Row],[xGA]]^2)*100 -> 55.577359 | T7: =INTERCEPT($E$2:$E$33,$M$2:$M$33)+SLOPE($E$2:$E$33,$M$2:$M$33)*M7 -> 60.843017 | U7: =E7-R7 -> 4.6363136 | V7: =Table1[[#This Row],[PTS%]]-Table1[[#This Row],[PyThagWin%]] -> 2.1255399 | W7: =Table1[[#This Row],[PTS%]]-Table1[[#This Row],[XGDiffPythag]] -> 9.4226408 | X7: =Table1[[#This Row],[PTS%]]-Table1[[#This Row],[XGDiffPts%]] -> 4.156983 | Y7: =Table1[[#This Row],[PyThagWin%]]-Table1[[#This Row],[XGDiffPythag]] -> 7.2971009 | Z7: =ABS(Y7)/Q7 -> 0.11605827 | AA7: PDO | AB7: =AVERAGE(F:F) -> 163.28125
A8: 7 | B8: Minnesota Wild* | C8: 171.6 | D8: 176.2 | E8: =100*0.638 -> 63.8 | F8: 164 | G8: 153 | H8: 100.7 | I8: 2342 | J8: 2351 | K8: =F8-C8 -> -7.6 | L8: =G8-D8 -> -23.2 | M8: =C8-D8 -> -4.6 | N8: =K8-L8 -> 15.6 | O8: =F8-G8 -> 11 | P8: =I8-J8 -> -9 | Q8: =Table1[[#This Row],[aGF]]^2/(Table1[[#This Row],[aGF]]^2+Table1[[#This Row],[aGA]]^2)*100 -> 53.465858 | R8: =INTERCEPT($E$2:$E$33,$N$2:$N$33)+SLOPE($E$2:$E$33,$N$2:$N$33)*N8 -> 58.825956 | S8: =Table1[[#This Row],[xGF]]^2/(Table1[[#This Row],[xGF]]^2+Table1[[#This Row],[xGA]]^2)*100 -> 48.677632 | T8: =INTERCEPT($E$2:$E$33,$M$2:$M$33)+SLOPE($E$2:$E$33,$M$2:$M$33)*M8 -> 55.170925 | U8: =E8-R8 -> 4.9740441 | V8: =Table1[[#This Row],[PTS%]]-Table1[[#This Row],[PyThagWin%]] -> 10.334142 | W8: =Table1[[#This Row],[PTS%]]-Table1[[#This Row],[XGDiffPythag]] -> 15.122368 | X8: =Table1[[#This Row],[PTS%]]-Table1[[#This Row],[XGDiffPts%]] -> 8.6290751 | Y8: =Table1[[#This Row],[PyThagWin%]]-Table1[[#This Row],[XGDiffPythag]] -> 4.7882261 | Z8: =ABS(Y8)/Q8 -> 0.089556706 | AA8: S | AB8: =AVERAGE(G:G) -> 163.28125
A9: 8 | B9: Boston Bruins | C9: 154.4 | D9: 178.9 | E9: =100*0.605 -> 60.5 | F9: 178 | G9: 150 | H9: 101.7 | I9: 2190 | J9: 2414 | K9: =F9-C9 -> 23.6 | L9: =G9-D9 -> -28.9 | M9: =C9-D9 -> -24.5 | N9: =K9-L9 -> 52.5 | O9: =F9-G9 -> 28 | P9: =I9-J9 -> -224 | Q9: =Table1[[#This Row],[aGF]]^2/(Table1[[#This Row],[aGF]]^2+Table1[[#This Row],[aGA]]^2)*100 -> 58.474827 | R9: =INTERCEPT($E$2:$E$33,$N$2:$N$33)+SLOPE($E$2:$E$33,$N$2:$N$33)*N9 -> 64.862366 | S9: =Table1[[#This Row],[xGF]]^2/(Table1[[#This Row],[xGF]]^2+Table1[[#This Row],[xGA]]^2)*100 -> 42.68877 | T9: =INTERCEPT($E$2:$E$33,$M$2:$M$33)+SLOPE($E$2:$E$33,$M$2:$M$33)*M9 -> 50.388101 | U9: =E9-R9 -> -4.3623662 | V9: =Table1[[#This Row],[PTS%]]-Table1[[#This Row],[PyThagWin%]] -> 2.0251735 | W9: =Table1[[#This Row],[PTS%]]-Table1[[#This Row],[XGDiffPythag]] -> 17.81123 | X9: =Table1[[#This Row],[PTS%]]-Table1[[#This Row],[XGDiffPts%]] -> 10.111899 | Y9: =Table1[[#This Row],[PyThagWin%]]-Table1[[#This Row],[XGDiffPythag]] -> 15.786057 | Z9: =ABS(Y9)/Q9 -> 0.26996329 | AA9: SA | AB9: =AVERAGE(H:H) -> 100.00312
A10: 9 | B10: Pittsburgh Penguins | C10: 195.2 | D10: 176.6 | E10: =100*0.605 -> 60.5 | F10: 196 | G10: 168 | H10: 101 | I10: 2320 | J10: 2213 | K10: =F10-C10 -> 0.8 | L10: =G10-D10 -> -8.6 | M10: =C10-D10 -> 18.6 | N10: =K10-L10 -> 9.4 | O10: =F10-G10 -> 28 | P10: =I10-J10 -> 107 | Q10: =Table1[[#This Row],[aGF]]^2/(Table1[[#This Row],[aGF]]^2+Table1[[#This Row],[aGA]]^2)*100 -> 57.647059 | R10: =INTERCEPT($E$2:$E$33,$N$2:$N$33)+SLOPE($E$2:$E$33,$N$2:$N$33)*N10 -> 57.811708 | S10: =Table1[[#This Row],[xGF]]^2/(Table1[[#This Row],[xGF]]^2+Table1[[#This Row],[xGA]]^2)*100 -> 54.990201 | T10: =INTERCEPT($E$2:$E$33,$M$2:$M$33)+SLOPE($E$2:$E$33,$M$2:$M$33)*M10 -> 60.74688 | U10: =E10-R10 -> 2.6882919 | V10: =Table1[[#This Row],[PTS%]]-Table1[[#This Row],[PyThagWin%]] -> 2.8529412 | W10: =Table1[[#This Row],[PTS%]]-Table1[[#This Row],[XGDiffPythag]] -> 5.5097993 | X10: =Table1[[#This Row],[PTS%]]-Table1[[#This Row],[XGDiffPts%]] -> -0.24687984 | Y10: =Table1[[#This Row],[PyThagWin%]]-Table1[[#This Row],[XGDiffPythag]] -> 2.6568581 | Z10: =ABS(Y10)/Q10 -> 0.046088355 | AA10: GF−xGF | AB10: =AVERAGE(K:K) -> -6.1625
A11: 10 | B11: Ottawa Senators | C11: 180.1 | D11: 144.3 | E11: =100*0.599 -> 59.9 | F11: 179 | G11: 162 | H11: 99.5 | I11: 2331 | J11: 1980 | K11: =F11-C11 -> -1.1 | L11: =G11-D11 -> 17.7 | M11: =C11-D11 -> 35.8 | N11: =K11-L11 -> -18.8 | O11: =F11-G11 -> 17 | P11: =I11-J11 -> 351 | Q11: =Table1[[#This Row],[aGF]]^2/(Table1[[#This Row],[aGF]]^2+Table1[[#This Row],[aGA]]^2)*100 -> 54.972978 | R11: =INTERCEPT($E$2:$E$33,$N$2:$N$33)+SLOPE($E$2:$E$33,$N$2:$N$33)*N11 -> 53.198517 | S11: =Table1[[#This Row],[xGF]]^2/(Table1[[#This Row],[xGF]]^2+Table1[[#This Row],[xGA]]^2)*100 -> 60.902973 | T11: =INTERCEPT($E$2:$E$33,$M$2:$M$33)+SLOPE($E$2:$E$33,$M$2:$M$33)*M11 -> 64.880777 | U11: =E11-R11 -> 6.7014835 | V11: =Table1[[#This Row],[PTS%]]-Table1[[#This Row],[PyThagWin%]] -> 4.9270224 | W11: =Table1[[#This Row],[PTS%]]-Table1[[#This Row],[XGDiffPythag]] -> -1.0029732 | X11: =Table1[[#This Row],[PTS%]]-Table1[[#This Row],[XGDiffPts%]] -> -4.9807775 | Y11: =Table1[[#This Row],[PyThagWin%]]-Table1[[#This Row],[XGDiffPythag]] -> -5.9299956 | Z11: =ABS(Y11)/Q11 -> 0.1078711 | AA11: GA−xGA | AB11: =AVERAGE(L:L) -> -6.16875
A12: 11 | B12: Philadelphia Flyers | C12: 159.9 | D12: 144.4 | E12: =100*0.588 -> 58.8 | F12: 158 | G12: 146 | H12: 100.6 | I12: 2040 | J12: 2032 | K12: =F12-C12 -> -1.9 | L12: =G12-D12 -> 1.6 | M12: =C12-D12 -> 15.5 | N12: =K12-L12 -> -3.5 | O12: =F12-G12 -> 12 | P12: =I12-J12 -> 8 | Q12: =Table1[[#This Row],[aGF]]^2/(Table1[[#This Row],[aGF]]^2+Table1[[#This Row],[aGA]]^2)*100 -> 53.941227 | R12: =INTERCEPT($E$2:$E$33,$N$2:$N$33)+SLOPE($E$2:$E$33,$N$2:$N$33)*N12 -> 55.701418 | S12: =Table1[[#This Row],[xGF]]^2/(Table1[[#This Row],[xGF]]^2+Table1[[#This Row],[xGA]]^2)*100 -> 55.080476 | T12: =INTERCEPT($E$2:$E$33,$M$2:$M$33)+SLOPE($E$2:$E$33,$M$2:$M$33)*M12 -> 60.001817 | U12: =E12-R12 -> 3.0985817 | V12: =Table1[[#This Row],[PTS%]]-Table1[[#This Row],[PyThagWin%]] -> 4.8587727 | W12: =Table1[[#This Row],[PTS%]]-Table1[[#This Row],[XGDiffPythag]] -> 3.7195239 | X12: =Table1[[#This Row],[PTS%]]-Table1[[#This Row],[XGDiffPts%]] -> -1.2018169 | Y12: =Table1[[#This Row],[PyThagWin%]]-Table1[[#This Row],[XGDiffPythag]] -> -1.1392488 | Z12: =ABS(Y12)/Q12 -> 0.021120187 | AA12: xGDiff | AB12: =AVERAGE(M:M) -> -0.00625
A13: 12 | B13: Washington Capitals | C13: 173.8 | D13: 169.3 | E13: =100*0.574 -> 57.4 | F13: 178 | G13: 146 | H13: 101.5 | I13: 2276 | J13: 2280 | K13: =F13-C13 -> 4.2 | L13: =G13-D13 -> -23.3 | M13: =C13-D13 -> 4.5 | N13: =K13-L13 -> 27.5 | O13: =F13-G13 -> 32 | P13: =I13-J13 -> -4 | Q13: =Table1[[#This Row],[aGF]]^2/(Table1[[#This Row],[aGF]]^2+Table1[[#This Row],[aGA]]^2)*100 -> 59.781132 | R13: =INTERCEPT($E$2:$E$33,$N$2:$N$33)+SLOPE($E$2:$E$33,$N$2:$N$33)*N13 -> 60.772657 | S13: =Table1[[#This Row],[xGF]]^2/(Table1[[#This Row],[xGF]]^2+Table1[[#This Row],[xGA]]^2)*100 -> 51.311345 | T13: =INTERCEPT($E$2:$E$33,$M$2:$M$33)+SLOPE($E$2:$E$33,$M$2:$M$33)*M13 -> 57.358045 | U13: =E13-R13 -> -3.3726573 | V13: =Table1[[#This Row],[PTS%]]-Table1[[#This Row],[PyThagWin%]] -> -2.3811321 | W13: =Table1[[#This Row],[PTS%]]-Table1[[#This Row],[XGDiffPythag]] -> 6.0886546 | X13: =Table1[[#This Row],[PTS%]]-Table1[[#This Row],[XGDiffPts%]] -> 0.041954865 | Y13: =Table1[[#This Row],[PyThagWin%]]-Table1[[#This Row],[XGDiffPythag]] -> 8.4697867 | Z13: =ABS(Y13)/Q13 -> 0.14167993 | AA13: Net Luck | AB13: =AVERAGE(N:N) -> 0.00625
A14: 13 | B14: Columbus Blue Jackets | C14: 180.4 | D14: 177.5 | E14: =100*0.568 -> 56.8 | F14: 173 | G14: 161 | H14: 100.3 | I14: 2382 | J14: 2341 | K14: =F14-C14 -> -7.4 | L14: =G14-D14 -> -16.5 | M14: =C14-D14 -> 2.9 | N14: =K14-L14 -> 9.1 | O14: =F14-G14 -> 12 | P14: =I14-J14 -> 41 | Q14: =Table1[[#This Row],[aGF]]^2/(Table1[[#This Row],[aGF]]^2+Table1[[#This Row],[aGA]]^2)*100 -> 53.588183 | R14: =INTERCEPT($E$2:$E$33,$N$2:$N$33)+SLOPE($E$2:$E$33,$N$2:$N$33)*N14 -> 57.762632 | S14: =Table1[[#This Row],[xGF]]^2/(Table1[[#This Row],[xGF]]^2+Table1[[#This Row],[xGA]]^2)*100 -> 50.810229 | T14: =INTERCEPT($E$2:$E$33,$M$2:$M$33)+SLOPE($E$2:$E$33,$M$2:$M$33)*M14 -> 56.973497 | U14: =E14-R14 -> -0.9626316 | V14: =Table1[[#This Row],[PTS%]]-Table1[[#This Row],[PyThagWin%]] -> 3.2118174 | W14: =Table1[[#This Row],[PTS%]]-Table1[[#This Row],[XGDiffPythag]] -> 5.989771 | X14: =Table1[[#This Row],[PTS%]]-Table1[[#This Row],[XGDiffPts%]] -> -0.17349652 | Y14: =Table1[[#This Row],[PyThagWin%]]-Table1[[#This Row],[XGDiffPythag]] -> 2.7779536 | Z14: =ABS(Y14)/Q14 -> 0.051838922 | AA14: Gdiff | AB14: =AVERAGE(O:O) -> 0
A15: 14 | B15: New York Islanders | C15: 167.4 | D15: 181 | E15: =100*0.562 -> 56.2 | F15: 145 | G15: 157 | H15: 99.5 | I15: 2278 | J15: 2249 | K15: =F15-C15 -> -22.4 | L15: =G15-D15 -> -24 | M15: =C15-D15 -> -13.6 | N15: =K15-L15 -> 1.6 | O15: =F15-G15 -> -12 | P15: =I15-J15 -> 29 | Q15: =Table1[[#This Row],[aGF]]^2/(Table1[[#This Row],[aGF]]^2+Table1[[#This Row],[aGA]]^2)*100 -> 46.032754 | R15: =INTERCEPT($E$2:$E$33,$N$2:$N$33)+SLOPE($E$2:$E$33,$N$2:$N$33)*N15 -> 56.535719 | S15: =Table1[[#This Row],[xGF]]^2/(Table1[[#This Row],[xGF]]^2+Table1[[#This Row],[xGA]]^2)*100 -> 46.10238 | T15: =INTERCEPT($E$2:$E$33,$M$2:$M$33)+SLOPE($E$2:$E$33,$M$2:$M$33)*M15 -> 53.007839 | U15: =E15-R15 -> -0.33571894 | V15: =Table1[[#This Row],[PTS%]]-Table1[[#This Row],[PyThagWin%]] -> 10.167246 | W15: =Table1[[#This Row],[PTS%]]-Table1[[#This Row],[XGDiffPythag]] -> 10.09762 | X15: =Table1[[#This Row],[PTS%]]-Table1[[#This Row],[XGDiffPts%]] -> 3.1921611 | Y15: =Table1[[#This Row],[PyThagWin%]]-Table1[[#This Row],[XGDiffPythag]] -> -0.069626113 | Z15: =ABS(Y15)/Q15 -> 0.0015125342 | AA15: Sdiff | AB15: =AVERAGE(P:P) -> 0
A16: 15 | B16: Detroit Red Wings | C16: 166.1 | D16: 168 | E16: =100*0.569 -> 56.9 | F16: 139 | G16: 159 | H16: 99.1 | I16: 2258 | J16: 2225 | K16: =F16-C16 -> -27.1 | L16: =G16-D16 -> -9 | M16: =C16-D16 -> -1.9 | N16: =K16-L16 -> -18.1 | O16: =F16-G16 -> -20 | P16: =I16-J16 -> 33 | Q16: =Table1[[#This Row],[aGF]]^2/(Table1[[#This Row],[aGF]]^2+Table1[[#This Row],[aGA]]^2)*100 -> 43.318685 | R16: =INTERCEPT($E$2:$E$33,$N$2:$N$33)+SLOPE($E$2:$E$33,$N$2:$N$33)*N16 -> 53.313028 | S16: =Table1[[#This Row],[xGF]]^2/(Table1[[#This Row],[xGF]]^2+Table1[[#This Row],[xGA]]^2)*100 -> 49.431326 | T16: =INTERCEPT($E$2:$E$33,$M$2:$M$33)+SLOPE($E$2:$E$33,$M$2:$M$33)*M16 -> 55.819851 | U16: =E16-R16 -> 3.5869716 | V16: =Table1[[#This Row],[PTS%]]-Table1[[#This Row],[PyThagWin%]] -> 13.581315 | W16: =Table1[[#This Row],[PTS%]]-Table1[[#This Row],[XGDiffPythag]] -> 7.4686736 | X16: =Table1[[#This Row],[PTS%]]-Table1[[#This Row],[XGDiffPts%]] -> 1.0801493 | Y16: =Table1[[#This Row],[PyThagWin%]]-Table1[[#This Row],[XGDiffPythag]] -> -6.1126411 | Z16: =ABS(Y16)/Q16 -> 0.14110865
A17: 16 | B17: Vegas Golden Knights | C17: 176.5 | D17: 144.4 | E17: =100*0.569 -> 56.9 | F17: 168 | G17: 170 | H17: 98.3 | I17: 2313 | J17: 1953 | K17: =F17-C17 -> -8.5 | L17: =G17-D17 -> 25.6 | M17: =C17-D17 -> 32.1 | N17: =K17-L17 -> -34.1 | O17: =F17-G17 -> -2 | P17: =I17-J17 -> 360 | Q17: =Table1[[#This Row],[aGF]]^2/(Table1[[#This Row],[aGF]]^2+Table1[[#This Row],[aGA]]^2)*100 -> 49.408305 | R17: =INTERCEPT($E$2:$E$33,$N$2:$N$33)+SLOPE($E$2:$E$33,$N$2:$N$33)*N17 -> 50.695615 | S17: =Table1[[#This Row],[xGF]]^2/(Table1[[#This Row],[xGF]]^2+Table1[[#This Row],[xGA]]^2)*100 -> 59.904014 | T17: =INTERCEPT($E$2:$E$33,$M$2:$M$33)+SLOPE($E$2:$E$33,$M$2:$M$33)*M17 -> 63.991509 | U17: =E17-R17 -> 6.2043853 | V17: =Table1[[#This Row],[PTS%]]-Table1[[#This Row],[PyThagWin%]] -> 7.4916953 | W17: =Table1[[#This Row],[PTS%]]-Table1[[#This Row],[XGDiffPythag]] -> -3.0040144 | X17: =Table1[[#This Row],[PTS%]]-Table1[[#This Row],[XGDiffPts%]] -> -7.0915088 | Y17: =Table1[[#This Row],[PyThagWin%]]-Table1[[#This Row],[XGDiffPythag]] -> -10.49571 | Z17: =ABS(Y17)/Q17 -> 0.21242805
A18: 17 | B18: Edmonton Oilers | C18: 186.6 | D18: 170.3 | E18: =100*0.563 -> 56.3 | F18: 170 | G18: 186 | H18: 98.4 | I18: 2373 | J18: 2144 | K18: =F18-C18 -> -16.6 | L18: =G18-D18 -> 15.7 | M18: =C18-D18 -> 16.3 | N18: =K18-L18 -> -32.3 | O18: =F18-G18 -> -16 | P18: =I18-J18 -> 229 | Q18: =Table1[[#This Row],[aGF]]^2/(Table1[[#This Row],[aGF]]^2+Table1[[#This Row],[aGA]]^2)*100 -> 45.514678 | R18: =INTERCEPT($E$2:$E$33,$N$2:$N$33)+SLOPE($E$2:$E$33,$N$2:$N$33)*N18 -> 50.990074 | S18: =Table1[[#This Row],[xGF]]^2/(Table1[[#This Row],[xGF]]^2+Table1[[#This Row],[xGA]]^2)*100 -> 54.557599 | T18: =INTERCEPT($E$2:$E$33,$M$2:$M$33)+SLOPE($E$2:$E$33,$M$2:$M$33)*M18 -> 60.194091 | U18: =E18-R18 -> 5.3099263 | V18: =Table1[[#This Row],[PTS%]]-Table1[[#This Row],[PyThagWin%]] -> 10.785322 | W18: =Table1[[#This Row],[PTS%]]-Table1[[#This Row],[XGDiffPythag]] -> 1.7424008 | X18: =Table1[[#This Row],[PTS%]]-Table1[[#This Row],[XGDiffPts%]] -> -3.8940912 | Y18: =Table1[[#This Row],[PyThagWin%]]-Table1[[#This Row],[XGDiffPythag]] -> -9.0429211 | Z18: =ABS(Y18)/Q18 -> 0.19868142
A19: 18 | B19: Anaheim Ducks | C19: 179.9 | D19: 176 | E19: =100*0.563 -> 56.3 | F19: 167 | G19: 185 | H19: 98.6 | I19: 2449 | J19: 2285 | K19: =F19-C19 -> -12.9 | L19: =G19-D19 -> 9 | M19: =C19-D19 -> 3.9 | N19: =K19-L19 -> -21.9 | O19: =F19-G19 -> -18 | P19: =I19-J19 -> 164 | Q19: =Table1[[#This Row],[aGF]]^2/(Table1[[#This Row],[aGF]]^2+Table1[[#This Row],[aGA]]^2)*100 -> 44.899701 | R19: =INTERCEPT($E$2:$E$33,$N$2:$N$33)+SLOPE($E$2:$E$33,$N$2:$N$33)*N19 -> 52.691393 | S19: =Table1[[#This Row],[xGF]]^2/(Table1[[#This Row],[xGF]]^2+Table1[[#This Row],[xGA]]^2)*100 -> 51.095682 | T19: =INTERCEPT($E$2:$E$33,$M$2:$M$33)+SLOPE($E$2:$E$33,$M$2:$M$33)*M19 -> 57.213839 | U19: =E19-R19 -> 3.6086074 | V19: =Table1[[#This Row],[PTS%]]-Table1[[#This Row],[PyThagWin%]] -> 11.400299 | W19: =Table1[[#This Row],[PTS%]]-Table1[[#This Row],[XGDiffPythag]] -> 5.2043181 | X19: =Table1[[#This Row],[PTS%]]-Table1[[#This Row],[XGDiffPts%]] -> -0.9138394 | Y19: =Table1[[#This Row],[PyThagWin%]]-Table1[[#This Row],[XGDiffPythag]] -> -6.1959813 | Z19: =ABS(Y19)/Q19 -> 0.13799605
A20: 19 | B20: Utah Mammoth | C20: 178.4 | D20: 153.6 | E20: =100*0.563 -> 56.3 | F20: 180 | G20: 158 | H20: 100.3 | I20: 2215 | J20: 2089 | K20: =F20-C20 -> 1.6 | L20: =G20-D20 -> 4.4 | M20: =C20-D20 -> 24.8 | N20: =K20-L20 -> -2.8 | O20: =F20-G20 -> 22 | P20: =I20-J20 -> 126 | Q20: =Table1[[#This Row],[aGF]]^2/(Table1[[#This Row],[aGF]]^2+Table1[[#This Row],[aGA]]^2)*100 -> 56.481417 | R20: =INTERCEPT($E$2:$E$33,$N$2:$N$33)+SLOPE($E$2:$E$33,$N$2:$N$33)*N20 -> 55.81593 | S20: =Table1[[#This Row],[xGF]]^2/(Table1[[#This Row],[xGF]]^2+Table1[[#This Row],[xGA]]^2)*100 -> 57.42843 | T20: =INTERCEPT($E$2:$E$33,$M$2:$M$33)+SLOPE($E$2:$E$33,$M$2:$M$33)*M20 -> 62.237006 | U20: =E20-R20 -> 0.48406982 | V20: =Table1[[#This Row],[PTS%]]-Table1[[#This Row],[PyThagWin%]] -> -0.18141692 | W20: =Table1[[#This Row],[PTS%]]-Table1[[#This Row],[XGDiffPythag]] -> -1.1284295 | X20: =Table1[[#This Row],[PTS%]]-Table1[[#This Row],[XGDiffPts%]] -> -5.9370057 | Y20: =Table1[[#This Row],[PyThagWin%]]-Table1[[#This Row],[XGDiffPythag]] -> -0.94701263 | Z20: =ABS(Y20)/Q20 -> 0.0167668
A21: 20 | B21: Los Angeles Kings | C21: 161.2 | D21: 154.7 | E21: =100*0.551 -> 55.1 | F21: 144 | G21: 135 | H21: 100.1 | I21: 2205 | J21: 2150 | K21: =F21-C21 -> -17.2 | L21: =G21-D21 -> -19.7 | M21: =C21-D21 -> 6.5 | N21: =K21-L21 -> 2.5 | O21: =F21-G21 -> 9 | P21: =I21-J21 -> 55 | Q21: =Table1[[#This Row],[aGF]]^2/(Table1[[#This Row],[aGF]]^2+Table1[[#This Row],[aGA]]^2)*100 -> 53.222453 | R21: =INTERCEPT($E$2:$E$33,$N$2:$N$33)+SLOPE($E$2:$E$33,$N$2:$N$33)*N21 -> 56.682948 | S21: =Table1[[#This Row],[xGF]]^2/(Table1[[#This Row],[xGF]]^2+Table1[[#This Row],[xGA]]^2)*100 -> 52.056742 | T21: =INTERCEPT($E$2:$E$33,$M$2:$M$33)+SLOPE($E$2:$E$33,$M$2:$M$33)*M21 -> 57.838731 | U21: =E21-R21 -> -1.5829485 | V21: =Table1[[#This Row],[PTS%]]-Table1[[#This Row],[PyThagWin%]] -> 1.8775468 | W21: =Table1[[#This Row],[PTS%]]-Table1[[#This Row],[XGDiffPythag]] -> 3.0432576 | X21: =Table1[[#This Row],[PTS%]]-Table1[[#This Row],[XGDiffPts%]] -> -2.7387309 | Y21: =Table1[[#This Row],[PyThagWin%]]-Table1[[#This Row],[XGDiffPythag]] -> 1.1657108 | Z21: =ABS(Y21)/Q21 -> 0.021902614
A22: 21 | B22: New Jersey Devils | C22: 178.2 | D22: 179.7 | E22: =100*0.537 -> 53.7 | F22: 136 | G22: 179 | H22: 97.6 | I22: 2405 | J22: 2218 | K22: =F22-C22 -> -42.2 | L22: =G22-D22 -> -0.7 | M22: =C22-D22 -> -1.5 | N22: =K22-L22 -> -41.5 | O22: =F22-G22 -> -43 | P22: =I22-J22 -> 187 | Q22: =Table1[[#This Row],[aGF]]^2/(Table1[[#This Row],[aGF]]^2+Table1[[#This Row],[aGA]]^2)*100 -> 36.598928 | R22: =INTERCEPT($E$2:$E$33,$N$2:$N$33)+SLOPE($E$2:$E$33,$N$2:$N$33)*N22 -> 49.485061 | S22: =Table1[[#This Row],[xGF]]^2/(Table1[[#This Row],[xGF]]^2+Table1[[#This Row],[xGA]]^2)*100 -> 49.580896 | T22: =INTERCEPT($E$2:$E$33,$M$2:$M$33)+SLOPE($E$2:$E$33,$M$2:$M$33)*M22 -> 55.915988 | U22: =E22-R22 -> 4.2149391 | V22: =Table1[[#This Row],[PTS%]]-Table1[[#This Row],[PyThagWin%]] -> 17.101072 | W22: =Table1[[#This Row],[PTS%]]-Table1[[#This Row],[XGDiffPythag]] -> 4.1191041 | X22: =Table1[[#This Row],[PTS%]]-Table1[[#This Row],[XGDiffPts%]] -> -2.2159878 | Y22: =Table1[[#This Row],[PyThagWin%]]-Table1[[#This Row],[XGDiffPythag]] -> -12.981968 | Z22: =ABS(Y22)/Q22 -> 0.35470898
A23: 22 | B23: Nashville Predators | C23: 171.8 | D23: 186.4 | E23: =100*0.538 -> 53.8 | F23: 148 | G23: 175 | H23: 99.4 | I23: 2235 | J23: 2367 | K23: =F23-C23 -> -23.8 | L23: =G23-D23 -> -11.4 | M23: =C23-D23 -> -14.6 | N23: =K23-L23 -> -12.4 | O23: =F23-G23 -> -27 | P23: =I23-J23 -> -132 | Q23: =Table1[[#This Row],[aGF]]^2/(Table1[[#This Row],[aGF]]^2+Table1[[#This Row],[aGA]]^2)*100 -> 41.698871 | R23: =INTERCEPT($E$2:$E$33,$N$2:$N$33)+SLOPE($E$2:$E$33,$N$2:$N$33)*N23 -> 54.245482 | S23: =Table1[[#This Row],[xGF]]^2/(Table1[[#This Row],[xGF]]^2+Table1[[#This Row],[xGA]]^2)*100 -> 45.930825 | T23: =INTERCEPT($E$2:$E$33,$M$2:$M$33)+SLOPE($E$2:$E$33,$M$2:$M$33)*M23 -> 52.767496 | U23: =E23-R23 -> -0.44548198 | V23: =Table1[[#This Row],[PTS%]]-Table1[[#This Row],[PyThagWin%]] -> 12.101129 | W23: =Table1[[#This Row],[PTS%]]-Table1[[#This Row],[XGDiffPythag]] -> 7.869175 | X23: =Table1[[#This Row],[PTS%]]-Table1[[#This Row],[XGDiffPts%]] -> 1.032504 | Y23: =Table1[[#This Row],[PyThagWin%]]-Table1[[#This Row],[XGDiffPythag]] -> -4.2319539 | Z23: =ABS(Y23)/Q23 -> 0.10148845
A24: 23 | B24: Winnipeg Jets | C24: 157.3 | D24: 164 | E24: =100*0.519 -> 51.9 | F24: 152 | G24: 161 | H24: 100.1 | I24: 2087 | J24: 2170 | K24: =F24-C24 -> -5.3 | L24: =G24-D24 -> -3 | M24: =C24-D24 -> -6.7 | N24: =K24-L24 -> -2.3 | O24: =F24-G24 -> -9 | P24: =I24-J24 -> -83 | Q24: =Table1[[#This Row],[aGF]]^2/(Table1[[#This Row],[aGF]]^2+Table1[[#This Row],[aGA]]^2)*100 -> 47.126976 | R24: =INTERCEPT($E$2:$E$33,$N$2:$N$33)+SLOPE($E$2:$E$33,$N$2:$N$33)*N24 -> 55.897724 | S24: =Table1[[#This Row],[xGF]]^2/(Table1[[#This Row],[xGF]]^2+Table1[[#This Row],[xGA]]^2)*100 -> 47.915628 | T24: =INTERCEPT($E$2:$E$33,$M$2:$M$33)+SLOPE($E$2:$E$33,$M$2:$M$33)*M24 -> 54.666205 | U24: =E24-R24 -> -3.9977244 | V24: =Table1[[#This Row],[PTS%]]-Table1[[#This Row],[PyThagWin%]] -> 4.773024 | W24: =Table1[[#This Row],[PTS%]]-Table1[[#This Row],[XGDiffPythag]] -> 3.9843722 | X24: =Table1[[#This Row],[PTS%]]-Table1[[#This Row],[XGDiffPts%]] -> -2.7662048 | Y24: =Table1[[#This Row],[PyThagWin%]]-Table1[[#This Row],[XGDiffPythag]] -> -0.78865178 | Z24: =ABS(Y24)/Q24 -> 0.016734615
A25: 24 | B25: San Jose Sharks | C25: 159.7 | D25: 174.2 | E25: =100*0.519 -> 51.9 | F25: 156 | G25: 183 | H25: 99.9 | I25: 2037 | J25: 2352 | K25: =F25-C25 -> -3.7 | L25: =G25-D25 -> 8.8 | M25: =C25-D25 -> -14.5 | N25: =K25-L25 -> -12.5 | O25: =F25-G25 -> -27 | P25: =I25-J25 -> -315 | Q25: =Table1[[#This Row],[aGF]]^2/(Table1[[#This Row],[aGF]]^2+Table1[[#This Row],[aGA]]^2)*100 -> 42.085603 | R25: =INTERCEPT($E$2:$E$33,$N$2:$N$33)+SLOPE($E$2:$E$33,$N$2:$N$33)*N25 -> 54.229123 | S25: =Table1[[#This Row],[xGF]]^2/(Table1[[#This Row],[xGF]]^2+Table1[[#This Row],[xGA]]^2)*100 -> 45.665556 | T25: =INTERCEPT($E$2:$E$33,$M$2:$M$33)+SLOPE($E$2:$E$33,$M$2:$M$33)*M25 -> 52.79153 | U25: =E25-R25 -> -2.3291231 | V25: =Table1[[#This Row],[PTS%]]-Table1[[#This Row],[PyThagWin%]] -> 9.8143969 | W25: =Table1[[#This Row],[PTS%]]-Table1[[#This Row],[XGDiffPythag]] -> 6.2344435 | X25: =Table1[[#This Row],[PTS%]]-Table1[[#This Row],[XGDiffPts%]] -> -0.89153028 | Y25: =Table1[[#This Row],[PyThagWin%]]-Table1[[#This Row],[XGDiffPythag]] -> -3.5799534 | Z25: =ABS(Y25)/Q25 -> 0.085063611
A26: 25 | B26: Florida Panthers | C26: 160.3 | D26: 164.9 | E26: =100*0.5 -> 50 | F26: 152 | G26: 178 | H26: 98.7 | I26: 2248 | J26: 2144 | K26: =F26-C26 -> -8.3 | L26: =G26-D26 -> 13.1 | M26: =C26-D26 -> -4.6 | N26: =K26-L26 -> -21.4 | O26: =F26-G26 -> -26 | P26: =I26-J26 -> 104 | Q26: =Table1[[#This Row],[aGF]]^2/(Table1[[#This Row],[aGF]]^2+Table1[[#This Row],[aGA]]^2)*100 -> 42.169818 | R26: =INTERCEPT($E$2:$E$33,$N$2:$N$33)+SLOPE($E$2:$E$33,$N$2:$N$33)*N26 -> 52.773187 | S26: =Table1[[#This Row],[xGF]]^2/(Table1[[#This Row],[xGF]]^2+Table1[[#This Row],[xGA]]^2)*100 -> 48.585769 | T26: =INTERCEPT($E$2:$E$33,$M$2:$M$33)+SLOPE($E$2:$E$33,$M$2:$M$33)*M26 -> 55.170925 | U26: =E26-R26 -> -2.7731868 | V26: =Table1[[#This Row],[PTS%]]-Table1[[#This Row],[PyThagWin%]] -> 7.8301818 | W26: =Table1[[#This Row],[PTS%]]-Table1[[#This Row],[XGDiffPythag]] -> 1.4142312 | X26: =Table1[[#This Row],[PTS%]]-Table1[[#This Row],[XGDiffPts%]] -> -5.1709249 | Y26: =Table1[[#This Row],[PyThagWin%]]-Table1[[#This Row],[XGDiffPythag]] -> -6.4159506 | Z26: =ABS(Y26)/Q26 -> 0.15214556
A27: 26 | B27: St. Louis Blues | C27: 159 | D27: 161 | E27: =100*0.506 -> 50.6 | F27: 150 | G27: 165 | H27: 99.7 | I27: 1993 | J27: 2195 | K27: =F27-C27 -> -9 | L27: =G27-D27 -> 4 | M27: =C27-D27 -> -2 | N27: =K27-L27 -> -13 | O27: =F27-G27 -> -15 | P27: =I27-J27 -> -202 | Q27: =Table1[[#This Row],[aGF]]^2/(Table1[[#This Row],[aGF]]^2+Table1[[#This Row],[aGA]]^2)*100 -> 45.248869 | R27: =INTERCEPT($E$2:$E$33,$N$2:$N$33)+SLOPE($E$2:$E$33,$N$2:$N$33)*N27 -> 54.147329 | S27: =Table1[[#This Row],[xGF]]^2/(Table1[[#This Row],[xGF]]^2+Table1[[#This Row],[xGA]]^2)*100 -> 49.375024 | T27: =INTERCEPT($E$2:$E$33,$M$2:$M$33)+SLOPE($E$2:$E$33,$M$2:$M$33)*M27 -> 55.795816 | U27: =E27-R27 -> -3.547329 | V27: =Table1[[#This Row],[PTS%]]-Table1[[#This Row],[PyThagWin%]] -> 5.3511312 | W27: =Table1[[#This Row],[PTS%]]-Table1[[#This Row],[XGDiffPythag]] -> 1.2249756 | X27: =Table1[[#This Row],[PTS%]]-Table1[[#This Row],[XGDiffPts%]] -> -5.1958164 | Y27: =Table1[[#This Row],[PyThagWin%]]-Table1[[#This Row],[XGDiffPythag]] -> -4.1261556 | Z27: =ABS(Y27)/Q27 -> 0.09118804
A28: 27 | B28: Seattle Kraken | C28: 150.3 | D28: 171.6 | E28: =100*0.5 -> 50 | F28: 150 | G28: 151 | H28: 101.2 | I28: 2021 | J28: 2324 | K28: =F28-C28 -> -0.3 | L28: =G28-D28 -> -20.6 | M28: =C28-D28 -> -21.3 | N28: =K28-L28 -> 20.3 | O28: =F28-G28 -> -1 | P28: =I28-J28 -> -303 | Q28: =Table1[[#This Row],[aGF]]^2/(Table1[[#This Row],[aGF]]^2+Table1[[#This Row],[aGA]]^2)*100 -> 49.667778 | R28: =INTERCEPT($E$2:$E$33,$N$2:$N$33)+SLOPE($E$2:$E$33,$N$2:$N$33)*N28 -> 59.594821 | S28: =Table1[[#This Row],[xGF]]^2/(Table1[[#This Row],[xGF]]^2+Table1[[#This Row],[xGA]]^2)*100 -> 43.411884 | T28: =INTERCEPT($E$2:$E$33,$M$2:$M$33)+SLOPE($E$2:$E$33,$M$2:$M$33)*M28 -> 51.157199 | U28: =E28-R28 -> -9.5948212 | V28: =Table1[[#This Row],[PTS%]]-Table1[[#This Row],[PyThagWin%]] -> 0.33222225 | W28: =Table1[[#This Row],[PTS%]]-Table1[[#This Row],[XGDiffPythag]] -> 6.5881163 | X28: =Table1[[#This Row],[PTS%]]-Table1[[#This Row],[XGDiffPts%]] -> -1.1571986 | Y28: =Table1[[#This Row],[PyThagWin%]]-Table1[[#This Row],[XGDiffPythag]] -> 6.255894 | Z28: =ABS(Y28)/Q28 -> 0.12595478
A29: 28 | B29: Toronto Maple Leafs | C29: 158.7 | D29: 192.5 | E29: =100*0.488 -> 48.8 | F29: 166 | G29: 202 | H29: 100.1 | I29: 2112 | J29: 2590 | K29: =F29-C29 -> 7.3 | L29: =G29-D29 -> 9.5 | M29: =C29-D29 -> -33.8 | N29: =K29-L29 -> -2.2 | O29: =F29-G29 -> -36 | P29: =I29-J29 -> -478 | Q29: =Table1[[#This Row],[aGF]]^2/(Table1[[#This Row],[aGF]]^2+Table1[[#This Row],[aGA]]^2)*100 -> 40.310123 | R29: =INTERCEPT($E$2:$E$33,$N$2:$N$33)+SLOPE($E$2:$E$33,$N$2:$N$33)*N29 -> 55.914083 | S29: =Table1[[#This Row],[xGF]]^2/(Table1[[#This Row],[xGF]]^2+Table1[[#This Row],[xGA]]^2)*100 -> 40.464179 | T29: =INTERCEPT($E$2:$E$33,$M$2:$M$33)+SLOPE($E$2:$E$33,$M$2:$M$33)*M29 -> 48.152913 | U29: =E29-R29 -> -7.1140832 | V29: =Table1[[#This Row],[PTS%]]-Table1[[#This Row],[PyThagWin%]] -> 8.4898771 | W29: =Table1[[#This Row],[PTS%]]-Table1[[#This Row],[XGDiffPythag]] -> 8.335821 | X29: =Table1[[#This Row],[PTS%]]-Table1[[#This Row],[XGDiffPts%]] -> 0.64708744 | Y29: =Table1[[#This Row],[PyThagWin%]]-Table1[[#This Row],[XGDiffPythag]] -> -0.1540561 | Z29: =ABS(Y29)/Q29 -> 0.003821772
A30: 29 | B30: Calgary Flames | C30: 164.4 | D30: 184.8 | E30: =100*0.469 -> 46.9 | F30: 141 | G30: 173 | H30: 98.6 | I30: 2254 | J30: 2387 | K30: =F30-C30 -> -23.4 | L30: =G30-D30 -> -11.8 | M30: =C30-D30 -> -20.4 | N30: =K30-L30 -> -11.6 | O30: =F30-G30 -> -32 | P30: =I30-J30 -> -133 | Q30: =Table1[[#This Row],[aGF]]^2/(Table1[[#This Row],[aGF]]^2+Table1[[#This Row],[aGA]]^2)*100 -> 39.913672 | R30: =INTERCEPT($E$2:$E$33,$N$2:$N$33)+SLOPE($E$2:$E$33,$N$2:$N$33)*N30 -> 54.376353 | S30: =Table1[[#This Row],[xGF]]^2/(Table1[[#This Row],[xGF]]^2+Table1[[#This Row],[xGA]]^2)*100 -> 44.177945 | T30: =INTERCEPT($E$2:$E$33,$M$2:$M$33)+SLOPE($E$2:$E$33,$M$2:$M$33)*M30 -> 51.373507 | U30: =E30-R30 -> -7.4763527 | V30: =Table1[[#This Row],[PTS%]]-Table1[[#This Row],[PyThagWin%]] -> 6.986328 | W30: =Table1[[#This Row],[PTS%]]-Table1[[#This Row],[XGDiffPythag]] -> 2.7220548 | X30: =Table1[[#This Row],[PTS%]]-Table1[[#This Row],[XGDiffPts%]] -> -4.4735072 | Y30: =Table1[[#This Row],[PyThagWin%]]-Table1[[#This Row],[XGDiffPythag]] -> -4.2642732 | Z30: =ABS(Y30)/Q30 -> 0.10683741
A31: 30 | B31: New York Rangers | C31: 152.4 | D31: 160 | E31: =100*0.469 -> 46.9 | F31: 148 | G31: 151 | H31: 100.8 | I31: 2018 | J31: 2315 | K31: =F31-C31 -> -4.4 | L31: =G31-D31 -> -9 | M31: =C31-D31 -> -7.6 | N31: =K31-L31 -> 4.6 | O31: =F31-G31 -> -3 | P31: =I31-J31 -> -297 | Q31: =Table1[[#This Row],[aGF]]^2/(Table1[[#This Row],[aGF]]^2+Table1[[#This Row],[aGA]]^2)*100 -> 48.996757 | R31: =INTERCEPT($E$2:$E$33,$N$2:$N$33)+SLOPE($E$2:$E$33,$N$2:$N$33)*N31 -> 57.026484 | S31: =Table1[[#This Row],[xGF]]^2/(Table1[[#This Row],[xGF]]^2+Table1[[#This Row],[xGA]]^2)*100 -> 47.56866 | T31: =INTERCEPT($E$2:$E$33,$M$2:$M$33)+SLOPE($E$2:$E$33,$M$2:$M$33)*M31 -> 54.449896 | U31: =E31-R31 -> -10.126484 | V31: =Table1[[#This Row],[PTS%]]-Table1[[#This Row],[PyThagWin%]] -> -2.0967565 | W31: =Table1[[#This Row],[PTS%]]-Table1[[#This Row],[XGDiffPythag]] -> -0.66866048 | X31: =Table1[[#This Row],[PTS%]]-Table1[[#This Row],[XGDiffPts%]] -> -7.5498962 | Y31: =Table1[[#This Row],[PyThagWin%]]-Table1[[#This Row],[XGDiffPythag]] -> 1.428096 | Z31: =ABS(Y31)/Q31 -> 0.029146746
A32: 31 | B32: Chicago Blackhawks | C32: 142.9 | D32: 201.8 | E32: =100*0.438 -> 43.8 | F32: 146 | G32: 192 | H32: 99.6 | I32: 1975 | J32: 2414 | K32: =F32-C32 -> 3.1 | L32: =G32-D32 -> -9.8 | M32: =C32-D32 -> -58.9 | N32: =K32-L32 -> 12.9 | O32: =F32-G32 -> -46 | P32: =I32-J32 -> -439 | Q32: =Table1[[#This Row],[aGF]]^2/(Table1[[#This Row],[aGF]]^2+Table1[[#This Row],[aGA]]^2)*100 -> 36.63802 | R32: =INTERCEPT($E$2:$E$33,$N$2:$N$33)+SLOPE($E$2:$E$33,$N$2:$N$33)*N32 -> 58.384267 | S32: =Table1[[#This Row],[xGF]]^2/(Table1[[#This Row],[xGF]]^2+Table1[[#This Row],[xGA]]^2)*100 -> 33.397434 | T32: =INTERCEPT($E$2:$E$33,$M$2:$M$33)+SLOPE($E$2:$E$33,$M$2:$M$33)*M32 -> 42.120306 | U32: =E32-R32 -> -14.584267 | V32: =Table1[[#This Row],[PTS%]]-Table1[[#This Row],[PyThagWin%]] -> 7.1619801 | W32: =Table1[[#This Row],[PTS%]]-Table1[[#This Row],[XGDiffPythag]] -> 10.402566 | X32: =Table1[[#This Row],[PTS%]]-Table1[[#This Row],[XGDiffPts%]] -> 1.6796939 | Y32: =Table1[[#This Row],[PyThagWin%]]-Table1[[#This Row],[XGDiffPythag]] -> 3.2405862 | Z32: =ABS(Y32)/Q32 -> 0.088448726
A33: 32 | B33: Vancouver Canucks | C33: 155.2 | D33: 194.4 | E33: =100*0.35 -> 35 | F33: 128 | G33: 204 | H33: 97.8 | I33: 2091 | J33: 2376 | K33: =F33-C33 -> -27.2 | L33: =G33-D33 -> 9.6 | M33: =C33-D33 -> -39.2 | N33: =K33-L33 -> -36.8 | O33: =F33-G33 -> -76 | P33: =I33-J33 -> -285 | Q33: =Table1[[#This Row],[aGF]]^2/(Table1[[#This Row],[aGF]]^2+Table1[[#This Row],[aGA]]^2)*100 -> 28.248276 | R33: =INTERCEPT($E$2:$E$33,$N$2:$N$33)+SLOPE($E$2:$E$33,$N$2:$N$33)*N33 -> 50.253926 | S33: =Table1[[#This Row],[xGF]]^2/(Table1[[#This Row],[xGF]]^2+Table1[[#This Row],[xGA]]^2)*100 -> 38.926411 | T33: =INTERCEPT($E$2:$E$33,$M$2:$M$33)+SLOPE($E$2:$E$33,$M$2:$M$33)*M33 -> 46.855061 | U33: =E33-R33 -> -15.253926 | V33: =Table1[[#This Row],[PTS%]]-Table1[[#This Row],[PyThagWin%]] -> 6.7517241 | W33: =Table1[[#This Row],[PTS%]]-Table1[[#This Row],[XGDiffPythag]] -> -3.9264105 | X33: =Table1[[#This Row],[PTS%]]-Table1[[#This Row],[XGDiffPts%]] -> -11.855061 | Y33: =Table1[[#This Row],[PyThagWin%]]-Table1[[#This Row],[XGDiffPythag]] -> -10.678135 | Z33: =ABS(Y33)/Q33 -> 0.37801014
B35: Data Pull
B36: Data Evaluated

Sheet Regression Analysis
A1: Simple Linear Regression — PTS% as Dependent Variable
A4: Model 1: PTS% vs xGDiff | D4: Summary Comparison | J4: Chart Data (live-linked)
A5: Slope | B5: =SLOPE(Data!E2:E33,Data!M2:M33) -> 0.24034289 | D5: Model | E5: Predictor | F5: R | G5: R² | H5: Std Error | J5: xGDiff | K5: PTS% | L5: Predicted | M5: NetLuck | N5: PTS% | O5: Predicted | P5: PyThagWin% | Q5: PTS% | R5: Predicted | S5: XPythagWin% | T5: PTS% | U5: Predicted | V5: PDO | W5: Net Luck | X5: Predicted
A6: Intercept | B6: =INTERCEPT(Data!E2:E33,Data!M2:M33) -> 56.276502 | D6: 1 | E6: xGDiff | F6: =B7 -> 0.70694263 | G6: =B8 -> 0.49976788 | H6: =B9 -> 5.6777307 | J6: =Data!M2 -> 50.5 | K6: =Data!E2 -> 72.8 | L6: =$B$6+$B$5*J6 -> 68.413818 | M6: =Data!N2 -> 34.5 | N6: =Data!E2 -> 72.8 | O6: =$B$15+$B$14*M6 -> 61.917776 | P6: =Data!Q2 -> 73.713926 | Q6: =Data!E2 -> 72.8 | R6: =$B$24+$B$23*P6 -> 73.513638 | S6: =Data!S2 -> 63.94697 | T6: =Data!E2 -> 72.8 | U6: =$B$33+$B$32*S6 -> 67.770448 | V6: ='PDO vs Net Luck'!B17 -> 101.7 | W6: ='PDO vs Net Luck'!C17 -> 34.5 | X6: ='PDO vs Net Luck'!D17 -> 28.366391
A7: R | B7: =CORREL(Data!E2:E33,Data!M2:M33) -> 0.70694263 | D7: 2 | E7: Net Luck | F7: =B16 -> 0.4814363 | G7: =B17 -> 0.23178091 | H7: =B18 -> 7.0360926 | J7: =Data!M3 -> 37.1 | K7: =Data!E3 -> 68.8 | L7: =$B$6+$B$5*J7 -> 65.193223 | M7: =Data!N3 -> -15.1 | N7: =Data!E3 -> 68.8 | O7: =$B$15+$B$14*M7 -> 53.803793 | P7: =Data!Q3 -> 56.44361 | Q7: =Data!E3 -> 68.8 | R7: =$B$24+$B$23*P7 -> 60.971828 | S7: =Data!S3 -> 60.317892 | T7: =Data!E3 -> 68.8 | U7: =$B$33+$B$32*S7 -> 64.773936 | V7: ='PDO vs Net Luck'!B18 -> 98.4 | W7: ='PDO vs Net Luck'!C18 -> -15.1 | X7: ='PDO vs Net Luck'!D18 -> -26.787033
A8: R² | B8: =RSQ(Data!E2:E33,Data!M2:M33) -> 0.49976788 | D8: 3 | E8: PyThagWin% | F8: =B25 -> 0.86075802 | G8: =B26 -> 0.74090436 | H8: =B27 -> 4.0861946 | J8: =Data!M4 -> 11.4 | K8: =Data!E4 -> 67.5 | L8: =$B$6+$B$5*J8 -> 59.016411 | M8: =Data!N4 -> 19.6 | N8: =Data!E4 -> 67.5 | O8: =$B$15+$B$14*M8 -> 59.480309 | P8: =Data!Q4 -> 60.393699 | Q8: =Data!E4 -> 67.5 | R8: =$B$24+$B$23*P8 -> 63.840407 | S8: =Data!S4 -> 53.609742 | T8: =Data!E4 -> 67.5 | U8: =$B$33+$B$32*S8 -> 59.23505 | V8: ='PDO vs Net Luck'!B19 -> 102.1 | W8: ='PDO vs Net Luck'!C19 -> 19.6 | X8: ='PDO vs Net Luck'!D19 -> 35.051655
A9: Std Error | B9: =STEYX(Data!E2:E33,Data!M2:M33) -> 5.6777307 | D9: 4 | E9: PDO | F9: =B34 -> 0.69936324 | G9: =B35 -> 0.48910894 | H9: =B36 -> 5.7379023 | J9: =Data!M5 -> -7.7 | K9: =Data!E5 -> 66.3 | L9: =$B$6+$B$5*J9 -> 54.425862 | M9: =Data!N5 -> 39.7 | N9: =Data!E5 -> 66.3 | O9: =$B$15+$B$14*M9 -> 62.768435 | P9: =Data!Q5 -> 59.329126 | Q9: =Data!E5 -> 66.3 | R9: =$B$24+$B$23*P9 -> 63.067307 | S9: =Data!S5 -> 47.811683 | T9: =Data!E5 -> 66.3 | U9: =$B$33+$B$32*S9 -> 54.44762 | V9: ='PDO vs Net Luck'!B20 -> 101.5 | W9: ='PDO vs Net Luck'!C20 -> 39.7 | X9: ='PDO vs Net Luck'!D20 -> 25.02376
A10: N | B10: =COUNT(Data!E2:E33) -> 32 | J10: =Data!M6 -> -1.7 | K10: =Data!E6 -> 65.4 | L10: =$B$6+$B$5*J10 -> 55.867919 | M10: =Data!N6 -> 25.7 | N10: =Data!E6 -> 65.4 | O10: =$B$15+$B$14*M10 -> 60.478198 | P10: =Data!Q6 -> 57.023826 | Q10: =Data!E6 -> 65.4 | R10: =$B$24+$B$23*P10 -> 61.393184 | S10: =Data!S6 -> 49.492702 | T10: =Data!E6 -> 65.4 | U10: =$B$33+$B$32*S10 -> 55.83563 | V10: ='PDO vs Net Luck'!B21 -> 101.6 | W10: ='PDO vs Net Luck'!C21 -> 25.7 | X10: ='PDO vs Net Luck'!D21 -> 26.695075
A11: Equation | B11: ="PTS% = "&ROUND(B6,4)&" + "&ROUND(B5,4)&" * xGDiff" -> PTS% = 56.2765 + 0.2403 * xGDiff | J11: =Data!M7 -> 19 | K11: =Data!E7 -> 65 | L11: =$B$6+$B$5*J11 -> 60.843017 | M11: =Data!N7 -> 25 | N11: =Data!E7 -> 65 | O11: =$B$15+$B$14*M11 -> 60.363686 | P11: =Data!Q7 -> 62.87446 | Q11: =Data!E7 -> 65 | R11: =$B$24+$B$23*P11 -> 65.641951 | S11: =Data!S7 -> 55.577359 | T11: =Data!E7 -> 65 | U11: =$B$33+$B$32*S11 -> 60.859702 | V11: ='PDO vs Net Luck'!B22 -> 101.7 | W11: ='PDO vs Net Luck'!C22 -> 25 | X11: ='PDO vs Net Luck'!D22 -> 28.366391
J12: =Data!M8 -> -4.6 | K12: =Data!E8 -> 63.8 | L12: =$B$6+$B$5*J12 -> 55.170925 | M12: =Data!N8 -> 15.6 | N12: =Data!E8 -> 63.8 | O12: =$B$15+$B$14*M12 -> 58.825956 | P12: =Data!Q8 -> 53.465858 | Q12: =Data!E8 -> 63.8 | R12: =$B$24+$B$23*P12 -> 58.809366 | S12: =Data!S8 -> 48.677632 | T12: =Data!E8 -> 63.8 | U12: =$B$33+$B$32*S12 -> 55.16263 | V12: ='PDO vs Net Luck'!B23 -> 100.7 | W12: ='PDO vs Net Luck'!C23 -> 15.6 | X12: ='PDO vs Net Luck'!D23 -> 11.653233
A13: Model 2: PTS% vs Net Luck | J13: =Data!M9 -> -24.5 | K13: =Data!E9 -> 60.5 | L13: =$B$6+$B$5*J13 -> 50.388101 | M13: =Data!N9 -> 52.5 | N13: =Data!E9 -> 60.5 | O13: =$B$15+$B$14*M13 -> 64.862366 | P13: =Data!Q9 -> 58.474827 | Q13: =Data!E9 -> 60.5 | R13: =$B$24+$B$23*P13 -> 62.44691 | S13: =Data!S9 -> 42.68877 | T13: =Data!E9 -> 60.5 | U13: =$B$33+$B$32*S13 -> 50.217656 | V13: ='PDO vs Net Luck'!B24 -> 101.7 | W13: ='PDO vs Net Luck'!C24 -> 52.5 | X13: ='PDO vs Net Luck'!D24 -> 28.366391
A14: Slope | B14: =SLOPE(Data!E2:E33,Data!N2:N33) -> 0.16358835 | J14: =Data!M10 -> 18.6 | K14: =Data!E10 -> 60.5 | L14: =$B$6+$B$5*J14 -> 60.74688 | M14: =Data!N10 -> 9.4 | N14: =Data!E10 -> 60.5 | O14: =$B$15+$B$14*M14 -> 57.811708 | P14: =Data!Q10 -> 57.647059 | Q14: =Data!E10 -> 60.5 | R14: =$B$24+$B$23*P14 -> 61.84578 | S14: =Data!S10 -> 54.990201 | T14: =Data!E10 -> 60.5 | U14: =$B$33+$B$32*S14 -> 60.374888 | V14: ='PDO vs Net Luck'!B25 -> 101 | W14: ='PDO vs Net Luck'!C25 -> 9.4 | X14: ='PDO vs Net Luck'!D25 -> 16.66718
A15: Intercept | B15: =INTERCEPT(Data!E2:E33,Data!N2:N33) -> 56.273978 | J15: =Data!M11 -> 35.8 | K15: =Data!E11 -> 59.9 | L15: =$B$6+$B$5*J15 -> 64.880777 | M15: =Data!N11 -> -18.8 | N15: =Data!E11 -> 59.9 | O15: =$B$15+$B$14*M15 -> 53.198517 | P15: =Data!Q11 -> 54.972978 | Q15: =Data!E11 -> 59.9 | R15: =$B$24+$B$23*P15 -> 59.903845 | S15: =Data!S11 -> 60.902973 | T15: =Data!E11 -> 59.9 | U15: =$B$33+$B$32*S15 -> 65.257035 | V15: ='PDO vs Net Luck'!B26 -> 99.5 | W15: ='PDO vs Net Luck'!C26 -> -18.8 | X15: ='PDO vs Net Luck'!D26 -> -8.402558
A16: R | B16: =CORREL(Data!E2:E33,Data!N2:N33) -> 0.4814363 | J16: =Data!M12 -> 15.5 | K16: =Data!E12 -> 58.8 | L16: =$B$6+$B$5*J16 -> 60.001817 | M16: =Data!N12 -> -3.5 | N16: =Data!E12 -> 58.8 | O16: =$B$15+$B$14*M16 -> 55.701418 | P16: =Data!Q12 -> 53.941227 | Q16: =Data!E12 -> 58.8 | R16: =$B$24+$B$23*P16 -> 59.154582 | S16: =Data!S12 -> 55.080476 | T16: =Data!E12 -> 58.8 | U16: =$B$33+$B$32*S16 -> 60.449428 | V16: ='PDO vs Net Luck'!B27 -> 100.6 | W16: ='PDO vs Net Luck'!C27 -> -3.5 | X16: ='PDO vs Net Luck'!D27 -> 9.9819167
A17: R² | B17: =RSQ(Data!E2:E33,Data!N2:N33) -> 0.23178091 | J17: =Data!M13 -> 4.5 | K17: =Data!E13 -> 57.4 | L17: =$B$6+$B$5*J17 -> 57.358045 | M17: =Data!N13 -> 27.5 | N17: =Data!E13 -> 57.4 | O17: =$B$15+$B$14*M17 -> 60.772657 | P17: =Data!Q13 -> 59.781132 | Q17: =Data!E13 -> 57.4 | R17: =$B$24+$B$23*P17 -> 63.395557 | S17: =Data!S13 -> 51.311345 | T17: =Data!E13 -> 57.4 | U17: =$B$33+$B$32*S17 -> 57.337275 | V17: ='PDO vs Net Luck'!B28 -> 101.5 | W17: ='PDO vs Net Luck'!C28 -> 27.5 | X17: ='PDO vs Net Luck'!D28 -> 25.02376
A18: Std Error | B18: =STEYX(Data!E2:E33,Data!N2:N33) -> 7.0360926 | J18: =Data!M14 -> 2.9 | K18: =Data!E14 -> 56.8 | L18: =$B$6+$B$5*J18 -> 56.973497 | M18: =Data!N14 -> 9.1 | N18: =Data!E14 -> 56.8 | O18: =$B$15+$B$14*M18 -> 57.762632 | P18: =Data!Q14 -> 53.588183 | Q18: =Data!E14 -> 56.8 | R18: =$B$24+$B$23*P18 -> 58.898199 | S18: =Data!S14 -> 50.810229 | T18: =Data!E14 -> 56.8 | U18: =$B$33+$B$32*S18 -> 56.923505 | V18: ='PDO vs Net Luck'!B29 -> 100.3 | W18: ='PDO vs Net Luck'!C29 -> 9.1 | X18: ='PDO vs Net Luck'!D29 -> 4.967969
A19: N | B19: =COUNT(Data!E2:E33) -> 32 | J19: =Data!M15 -> -13.6 | K19: =Data!E15 -> 56.2 | L19: =$B$6+$B$5*J19 -> 53.007839 | M19: =Data!N15 -> 1.6 | N19: =Data!E15 -> 56.2 | O19: =$B$15+$B$14*M19 -> 56.535719 | P19: =Data!Q15 -> 46.032754 | Q19: =Data!E15 -> 56.2 | R19: =$B$24+$B$23*P19 -> 53.411399 | S19: =Data!S15 -> 46.10238 | T19: =Data!E15 -> 56.2 | U19: =$B$33+$B$32*S19 -> 53.036257 | V19: ='PDO vs Net Luck'!B30 -> 99.5 | W19: ='PDO vs Net Luck'!C30 -> 1.6 | X19: ='PDO vs Net Luck'!D30 -> -8.402558
A20: Equation | B20: ="PTS% = "&ROUND(B15,4)&" + "&ROUND(B14,4)&" * NetLuck" -> PTS% = 56.274 + 0.1636 * NetLuck | J20: =Data!M16 -> -1.9 | K20: =Data!E16 -> 56.9 | L20: =$B$6+$B$5*J20 -> 55.819851 | M20: =Data!N16 -> -18.1 | N20: =Data!E16 -> 56.9 | O20: =$B$15+$B$14*M20 -> 53.313028 | P20: =Data!Q16 -> 43.318685 | Q20: =Data!E16 -> 56.9 | R20: =$B$24+$B$23*P20 -> 51.440426 | S20: =Data!S16 -> 49.431326 | T20: =Data!E16 -> 56.9 | U20: =$B$33+$B$32*S20 -> 55.784952 | V20: ='PDO vs Net Luck'!B31 -> 99.1 | W20: ='PDO vs Net Luck'!C31 -> -18.1 | X20: ='PDO vs Net Luck'!D31 -> -15.087822
J21: =Data!M17 -> 32.1 | K21: =Data!E17 -> 56.9 | L21: =$B$6+$B$5*J21 -> 63.991509 | M21: =Data!N17 -> -34.1 | N21: =Data!E17 -> 56.9 | O21: =$B$15+$B$14*M21 -> 50.695615 | P21: =Data!Q17 -> 49.408305 | Q21: =Data!E17 -> 56.9 | R21: =$B$24+$B$23*P21 -> 55.862745 | S21: =Data!S17 -> 59.904014 | T21: =Data!E17 -> 56.9 | U21: =$B$33+$B$32*S21 -> 64.4322 | V21: ='PDO vs Net Luck'!B32 -> 98.3 | W21: ='PDO vs Net Luck'!C32 -> -34.1 | X21: ='PDO vs Net Luck'!D32 -> -28.458349
A22: Model 3: PTS% vs PyThagWin% | J22: =Data!M18 -> 16.3 | K22: =Data!E18 -> 56.3 | L22: =$B$6+$B$5*J22 -> 60.194091 | M22: =Data!N18 -> -32.3 | N22: =Data!E18 -> 56.3 | O22: =$B$15+$B$14*M22 -> 50.990074 | P22: =Data!Q18 -> 45.514678 | Q22: =Data!E18 -> 56.3 | R22: =$B$24+$B$23*P22 -> 53.03517 | S22: =Data!S18 -> 54.557599 | T22: =Data!E18 -> 56.3 | U22: =$B$33+$B$32*S22 -> 60.017691 | V22: ='PDO vs Net Luck'!B33 -> 98.4 | W22: ='PDO vs Net Luck'!C33 -> -32.3 | X22: ='PDO vs Net Luck'!D33 -> -26.787033
A23: Slope | B23: =SLOPE(Data!E2:E33,Data!Q2:Q33) -> 0.7262062 | J23: =Data!M19 -> 3.9 | K23: =Data!E19 -> 56.3 | L23: =$B$6+$B$5*J23 -> 57.213839 | M23: =Data!N19 -> -21.9 | N23: =Data!E19 -> 56.3 | O23: =$B$15+$B$14*M23 -> 52.691393 | P23: =Data!Q19 -> 44.899701 | Q23: =Data!E19 -> 56.3 | R23: =$B$24+$B$23*P23 -> 52.588569 | S23: =Data!S19 -> 51.095682 | T23: =Data!E19 -> 56.3 | U23: =$B$33+$B$32*S23 -> 57.159202 | V23: ='PDO vs Net Luck'!B34 -> 98.6 | W23: ='PDO vs Net Luck'!C34 -> -21.9 | X23: ='PDO vs Net Luck'!D34 -> -23.444401
A24: Intercept | B24: =INTERCEPT(Data!E2:E33,Data!Q2:Q33) -> 19.982128 | J24: =Data!M20 -> 24.8 | K24: =Data!E20 -> 56.3 | L24: =$B$6+$B$5*J24 -> 62.237006 | M24: =Data!N20 -> -2.8 | N24: =Data!E20 -> 56.3 | O24: =$B$15+$B$14*M24 -> 55.81593 | P24: =Data!Q20 -> 56.481417 | Q24: =Data!E20 -> 56.3 | R24: =$B$24+$B$23*P24 -> 60.999283 | S24: =Data!S20 -> 57.42843 | T24: =Data!E20 -> 56.3 | U24: =$B$33+$B$32*S24 -> 62.388121 | V24: ='PDO vs Net Luck'!B35 -> 100.3 | W24: ='PDO vs Net Luck'!C35 -> -2.8 | X24: ='PDO vs Net Luck'!D35 -> 4.967969
A25: R | B25: =CORREL(Data!E2:E33,Data!Q2:Q33) -> 0.86075802 | J25: =Data!M21 -> 6.5 | K25: =Data!E21 -> 55.1 | L25: =$B$6+$B$5*J25 -> 57.838731 | M25: =Data!N21 -> 2.5 | N25: =Data!E21 -> 55.1 | O25: =$B$15+$B$14*M25 -> 56.682948 | P25: =Data!Q21 -> 53.222453 | Q25: =Data!E21 -> 55.1 | R25: =$B$24+$B$23*P25 -> 58.632604 | S25: =Data!S21 -> 52.056742 | T25: =Data!E21 -> 55.1 | U25: =$B$33+$B$32*S25 -> 57.952745 | V25: ='PDO vs Net Luck'!B36 -> 100.1 | W25: ='PDO vs Net Luck'!C36 -> 2.5 | X25: ='PDO vs Net Luck'!D36 -> 1.6253373
A26: R² | B26: =RSQ(Data!E2:E33,Data!Q2:Q33) -> 0.74090436 | J26: =Data!M22 -> -1.5 | K26: =Data!E22 -> 53.7 | L26: =$B$6+$B$5*J26 -> 55.915988 | M26: =Data!N22 -> -41.5 | N26: =Data!E22 -> 53.7 | O26: =$B$15+$B$14*M26 -> 49.485061 | P26: =Data!Q22 -> 36.598928 | Q26: =Data!E22 -> 53.7 | R26: =$B$24+$B$23*P26 -> 46.560496 | S26: =Data!S22 -> 49.580896 | T26: =Data!E22 -> 53.7 | U26: =$B$33+$B$32*S26 -> 55.908451 | V26: ='PDO vs Net Luck'!B37 -> 97.6 | W26: ='PDO vs Net Luck'!C37 -> -41.5 | X26: ='PDO vs Net Luck'!D37 -> -40.15756
A27: Std Error | B27: =STEYX(Data!E2:E33,Data!Q2:Q33) -> 4.0861946 | J27: =Data!M23 -> -14.6 | K27: =Data!E23 -> 53.8 | L27: =$B$6+$B$5*J27 -> 52.767496 | M27: =Data!N23 -> -12.4 | N27: =Data!E23 -> 53.8 | O27: =$B$15+$B$14*M27 -> 54.245482 | P27: =Data!Q23 -> 41.698871 | Q27: =Data!E23 -> 53.8 | R27: =$B$24+$B$23*P27 -> 50.264107 | S27: =Data!S23 -> 45.930825 | T27: =Data!E23 -> 53.8 | U27: =$B$33+$B$32*S27 -> 52.894605 | V27: ='PDO vs Net Luck'!B38 -> 99.4 | W27: ='PDO vs Net Luck'!C38 -> -12.4 | X27: ='PDO vs Net Luck'!D38 -> -10.073874
A28: N | B28: =COUNT(Data!E2:E33) -> 32 | J28: =Data!M24 -> -6.7 | K28: =Data!E24 -> 51.9 | L28: =$B$6+$B$5*J28 -> 54.666205 | M28: =Data!N24 -> -2.3 | N28: =Data!E24 -> 51.9 | O28: =$B$15+$B$14*M28 -> 55.897724 | P28: =Data!Q24 -> 47.126976 | Q28: =Data!E24 -> 51.9 | R28: =$B$24+$B$23*P28 -> 54.20603 | S28: =Data!S24 -> 47.915628 | T28: =Data!E24 -> 51.9 | U28: =$B$33+$B$32*S28 -> 54.533447 | V28: ='PDO vs Net Luck'!B39 -> 100.1 | W28: ='PDO vs Net Luck'!C39 -> -2.3 | X28: ='PDO vs Net Luck'!D39 -> 1.6253373
A29: Equation | B29: ="PTS% = "&ROUND(B24,4)&" + "&ROUND(B23,4)&" * PyThagWin%" -> PTS% = 19.9821 + 0.7262 * PyThagWin% | J29: =Data!M25 -> -14.5 | K29: =Data!E25 -> 51.9 | L29: =$B$6+$B$5*J29 -> 52.79153 | M29: =Data!N25 -> -12.5 | N29: =Data!E25 -> 51.9 | O29: =$B$15+$B$14*M29 -> 54.229123 | P29: =Data!Q25 -> 42.085603 | Q29: =Data!E25 -> 51.9 | R29: =$B$24+$B$23*P29 -> 50.544954 | S29: =Data!S25 -> 45.665556 | T29: =Data!E25 -> 51.9 | U29: =$B$33+$B$32*S29 -> 52.675574 | V29: ='PDO vs Net Luck'!B40 -> 99.9 | W29: ='PDO vs Net Luck'!C40 -> -12.5 | X29: ='PDO vs Net Luck'!D40 -> -1.7172945
J30: =Data!M26 -> -4.6 | K30: =Data!E26 -> 50 | L30: =$B$6+$B$5*J30 -> 55.170925 | M30: =Data!N26 -> -21.4 | N30: =Data!E26 -> 50 | O30: =$B$15+$B$14*M30 -> 52.773187 | P30: =Data!Q26 -> 42.169818 | Q30: =Data!E26 -> 50 | R30: =$B$24+$B$23*P30 -> 50.606112 | S30: =Data!S26 -> 48.585769 | T30: =Data!E26 -> 50 | U30: =$B$33+$B$32*S30 -> 55.086779 | V30: ='PDO vs Net Luck'!B41 -> 98.7 | W30: ='PDO vs Net Luck'!C41 -> -21.4 | X30: ='PDO vs Net Luck'!D41 -> -21.773085
A31: Model 4: PTS% vs XPythagWin% | J31: =Data!M27 -> -2 | K31: =Data!E27 -> 50.6 | L31: =$B$6+$B$5*J31 -> 55.795816 | M31: =Data!N27 -> -13 | N31: =Data!E27 -> 50.6 | O31: =$B$15+$B$14*M31 -> 54.147329 | P31: =Data!Q27 -> 45.248869 | Q31: =Data!E27 -> 50.6 | R31: =$B$24+$B$23*P31 -> 52.842137 | S31: =Data!S27 -> 49.375024 | T31: =Data!E27 -> 50.6 | U31: =$B$33+$B$32*S31 -> 55.738464 | V31: ='PDO vs Net Luck'!B42 -> 99.7 | W31: ='PDO vs Net Luck'!C42 -> -13 | X31: ='PDO vs Net Luck'!D42 -> -5.0599263
A32: Slope | B32: =SLOPE(Data!E2:E33,Data!S2:S33) -> 0.82569513 | J32: =Data!M28 -> -21.3 | K32: =Data!E28 -> 50 | L32: =$B$6+$B$5*J32 -> 51.157199 | M32: =Data!N28 -> 20.3 | N32: =Data!E28 -> 50 | O32: =$B$15+$B$14*M32 -> 59.594821 | P32: =Data!Q28 -> 49.667778 | Q32: =Data!E28 -> 50 | R32: =$B$24+$B$23*P32 -> 56.051176 | S32: =Data!S28 -> 43.411884 | T32: =Data!E28 -> 50 | U32: =$B$33+$B$32*S32 -> 50.814728 | V32: ='PDO vs Net Luck'!B43 -> 101.2 | W32: ='PDO vs Net Luck'!C43 -> 20.3 | X32: ='PDO vs Net Luck'!D43 -> 20.009812
A33: Intercept | B33: =INTERCEPT(Data!E2:E33,Data!S2:S33) -> 14.969747 | J33: =Data!M29 -> -33.8 | K33: =Data!E29 -> 48.8 | L33: =$B$6+$B$5*J33 -> 48.152913 | M33: =Data!N29 -> -2.2 | N33: =Data!E29 -> 48.8 | O33: =$B$15+$B$14*M33 -> 55.914083 | P33: =Data!Q29 -> 40.310123 | Q33: =Data!E29 -> 48.8 | R33: =$B$24+$B$23*P33 -> 49.255589 | S33: =Data!S29 -> 40.464179 | T33: =Data!E29 -> 48.8 | U33: =$B$33+$B$32*S33 -> 48.380822 | V33: ='PDO vs Net Luck'!B44 -> 100.1 | W33: ='PDO vs Net Luck'!C44 -> -2.2 | X33: ='PDO vs Net Luck'!D44 -> 1.6253373
A34: R | B34: =CORREL(Data!E2:E33,Data!S2:S33) -> 0.69936324 | J34: =Data!M30 -> -20.4 | K34: =Data!E30 -> 46.9 | L34: =$B$6+$B$5*J34 -> 51.373507 | M34: =Data!N30 -> -11.6 | N34: =Data!E30 -> 46.9 | O34: =$B$15+$B$14*M34 -> 54.376353 | P34: =Data!Q30 -> 39.913672 | Q34: =Data!E30 -> 46.9 | R34: =$B$24+$B$23*P34 -> 48.967684 | S34: =Data!S30 -> 44.177945 | T34: =Data!E30 -> 46.9 | U34: =$B$33+$B$32*S34 -> 51.447261 | V34: ='PDO vs Net Luck'!B45 -> 98.6 | W34: ='PDO vs Net Luck'!C45 -> -11.6 | X34: ='PDO vs Net Luck'!D45 -> -23.444401
A35: R² | B35: =RSQ(Data!E2:E33,Data!S2:S33) -> 0.48910894 | J35: =Data!M31 -> -7.6 | K35: =Data!E31 -> 46.9 | L35: =$B$6+$B$5*J35 -> 54.449896 | M35: =Data!N31 -> 4.6 | N35: =Data!E31 -> 46.9 | O35: =$B$15+$B$14*M35 -> 57.026484 | P35: =Data!Q31 -> 48.996757 | Q35: =Data!E31 -> 46.9 | R35: =$B$24+$B$23*P35 -> 55.563877 | S35: =Data!S31 -> 47.56866 | T35: =Data!E31 -> 46.9 | U35: =$B$33+$B$32*S35 -> 54.246958 | V35: ='PDO vs Net Luck'!B46 -> 100.8 | W35: ='PDO vs Net Luck'!C46 -> 4.6 | X35: ='PDO vs Net Luck'!D46 -> 13.324548
A36: Std Error | B36: =STEYX(Data!E2:E33,Data!S2:S33) -> 5.7379023 | J36: =Data!M32 -> -58.9 | K36: =Data!E32 -> 43.8 | L36: =$B$6+$B$5*J36 -> 42.120306 | M36: =Data!N32 -> 12.9 | N36: =Data!E32 -> 43.8 | O36: =$B$15+$B$14*M36 -> 58.384267 | P36: =Data!Q32 -> 36.63802 | Q36: =Data!E32 -> 43.8 | R36: =$B$24+$B$23*P36 -> 46.588885 | S36: =Data!S32 -> 33.397434 | T36: =Data!E32 -> 43.8 | U36: =$B$33+$B$32*S36 -> 42.545845 | V36: ='PDO vs Net Luck'!B47 -> 99.6 | W36: ='PDO vs Net Luck'!C47 -> 12.9 | X36: ='PDO vs Net Luck'!D47 -> -6.7312421
A37: N | B37: =COUNT(Data!E2:E33) -> 32 | J37: =Data!M33 -> -39.2 | K37: =Data!E33 -> 35 | L37: =$B$6+$B$5*J37 -> 46.855061 | M37: =Data!N33 -> -36.8 | N37: =Data!E33 -> 35 | O37: =$B$15+$B$14*M37 -> 50.253926 | P37: =Data!Q33 -> 28.248276 | Q37: =Data!E33 -> 35 | R37: =$B$24+$B$23*P37 -> 40.496201 | S37: =Data!S33 -> 38.926411 | T37: =Data!E33 -> 35 | U37: =$B$33+$B$32*S37 -> 47.111094 | V37: ='PDO vs Net Luck'!B48 -> 97.8 | W37: ='PDO vs Net Luck'!C48 -> -36.8 | X37: ='PDO vs Net Luck'!D48 -> -36.814928
A38: Equation | B38: ="PTS% = "&ROUND(B33,4)&" + "&ROUND(B32,4)&" * XPythagWin%" -> PTS% = 14.9697 + 0.8257 * XPythagWin%

Sheet PDO vs Net Luck
A1: Regression Analysis: PDO vs Net Luck
A3: Independent Variable (X): | B3: PDO
A4: Dependent Variable (Y): | B4: Net Luck
A6: Regression Statistics
A7: Slope | B7: =SLOPE(Data!N2:N33,Data!H2:H33) -> 16.713159
A8: Intercept | B8: =INTERCEPT(Data!N2:N33,Data!H2:H33) -> -1671.3619
A9: R | B9: =CORREL(Data!H2:H33,Data!N2:N33) -> 0.91720329
A10: R² | B10: =RSQ(Data!N2:N33,Data!H2:H33) -> 0.84126187
A11: Standard Error | B11: =STEYX(Data!N2:N33,Data!H2:H33) -> 9.4127404
A12: Observations | B12: =COUNT(Data!H2:H33) -> 32
A13: Regression Equation | B13: ="Net Luck = "&ROUND(B7,3)&" * PDO + "&ROUND(B8,3) -> Net Luck = 16.713 * PDO + -1671.362
A15: Data
A16: Team | B16: PDO | C16: Net Luck | D16: Predicted Net Luck | E16: Residual
A17: =Data!B2 -> Colorado Avalanche* | B17: =Data!H2 -> 101.7 | C17: =Data!N2 -> 34.5 | D17: =$B$7*B17+$B$8 -> 28.366391 | E17: =C17-D17 -> 6.1336087
A18: =Data!B3 -> Carolina Hurricanes | B18: =Data!H3 -> 98.4 | C18: =Data!N3 -> -15.1 | D18: =$B$7*B18+$B$8 -> -26.787033 | E18: =C18-D18 -> 11.687033
A19: =Data!B4 -> Dallas Stars* | B19: =Data!H4 -> 102.1 | C19: =Data!N4 -> 19.6 | D19: =$B$7*B19+$B$8 -> 35.051655 | E19: =C19-D19 -> -15.451655
A20: =Data!B5 -> Buffalo Sabres | B20: =Data!H5 -> 101.5 | C20: =Data!N5 -> 39.7 | D20: =$B$7*B20+$B$8 -> 25.02376 | E20: =C20-D20 -> 14.67624
A21: =Data!B6 -> Montreal Canadiens | B21: =Data!H6 -> 101.6 | C21: =Data!N6 -> 25.7 | D21: =$B$7*B21+$B$8 -> 26.695075 | E21: =C21-D21 -> -0.99507545
A22: =Data!B7 -> Tampa Bay Lightning | B22: =Data!H7 -> 101.7 | C22: =Data!N7 -> 25 | D22: =$B$7*B22+$B$8 -> 28.366391 | E22: =C22-D22 -> -3.3663913
A23: =Data!B8 -> Minnesota Wild* | B23: =Data!H8 -> 100.7 | C23: =Data!N8 -> 15.6 | D23: =$B$7*B23+$B$8 -> 11.653233 | E23: =C23-D23 -> 3.9467675
A24: =Data!B9 -> Boston Bruins | B24: =Data!H9 -> 101.7 | C24: =Data!N9 -> 52.5 | D24: =$B$7*B24+$B$8 -> 28.366391 | E24: =C24-D24 -> 24.133609
A25: =Data!B10 -> Pittsburgh Penguins | B25: =Data!H10 -> 101 | C25: =Data!N10 -> 9.4 | D25: =$B$7*B25+$B$8 -> 16.66718 | E25: =C25-D25 -> -7.2671802
A26: =Data!B11 -> Ottawa Senators | B26: =Data!H11 -> 99.5 | C26: =Data!N11 -> -18.8 | D26: =$B$7*B26+$B$8 -> -8.402558 | E26: =C26-D26 -> -10.397442
A27: =Data!B12 -> Philadelphia Flyers | B27: =Data!H12 -> 100.6 | C27: =Data!N12 -> -3.5 | D27: =$B$7*B27+$B$8 -> 9.9819167 | E27: =C27-D27 -> -13.481917
A28: =Data!B13 -> Washington Capitals | B28: =Data!H13 -> 101.5 | C28: =Data!N13 -> 27.5 | D28: =$B$7*B28+$B$8 -> 25.02376 | E28: =C28-D28 -> 2.4762404
... A48: =Data!B33 -> Vancouver Canucks | B48: =Data!H33 -> 97.8 | C48: =Data!N33 -> -36.8 | D48: =$B$7*B48+$B$8 -> -36.814928 | E48: =C48-D48 -> 0.014927963

Sheet Outlier Analysis
A1: Luck Analysis — Grand Scoring Across 3 Models
A2: Total = Grand Lucky − Grand Unlucky (net luck score). Luckiest sorted desc, Unluckiest sorted asc. Verdict bands use |Total|.
A4: GRAND LUCKIEST TEAMS (sorted by Total desc)
A5: Rank | B5: Team | C5: A1 Pts | D5: A2 Pts | E5: A3 Pts | F5: Total | G5: Verdict | H5: Notes
A6: =IF(LARGE('Step 1 Regressions'!$AD$9:$AD$40,1)<=0,"",1) -> 1 | B6: {=IF(LARGE('Step 1 Regressions'!$AD$9:$AD$40,1)<=0,"",INDEX('Step 1 Regressions'!$B$9:$B$40,MATCH(LARGE(('Step 1 Regressions'!$AD$9:$AD$40+ROW('Step 1 Regressions'!$AD$9:$AD$40)/1000000),1),('Step 1 Regressions'!$AD$9:$AD$40+ROW('Step 1 Regressions'!$AD$9:$AD$40)/1000000),0)))} -> Buffalo Sabres | C6: {=IF(LARGE('Step 1 Regressions'!$AD$9:$AD$40,1)<=0,"",INDEX('Step 1 Regressions'!$T$9:$T$40,MATCH(LARGE(('Step 1 Regressions'!$AD$9:$AD$40+ROW('Step 1 Regressions'!$AD$9:$AD$40)/1000000),1),('Step 1 Regressions'!$AD$9:$AD$40+ROW('Step 1 Regressions'!$AD$9:$AD$40)/1000000),0)))} -> 0 | D6: {=IF(LARGE('Step 1 Regressions'!$AD$9:$AD$40,1)<=0,"",INDEX('Step 1 Regressions'!$U$9:$U$40,MATCH(LARGE(('Step 1 Regressions'!$AD$9:$AD$40+ROW('Step 1 Regressions'!$AD$9:$AD$40)/1000000),1),('Step 1 Regressions'!$AD$9:$AD$40+ROW('Step 1 Regressions'!$AD$9:$AD$40)/1000000),0)))} -> 10 | E6: {=IF(LARGE('Step 1 Regressions'!$AD$9:$AD$40,1)<=0,"",INDEX('Step 1 Regressions'!$V$9:$V$40,MATCH(LARGE(('Step 1 Regressions'!$AD$9:$AD$40+ROW('Step 1 Regressions'!$AD$9:$AD$40)/1000000),1),('Step 1 Regressions'!$AD$9:$AD$40+ROW('Step 1 Regressions'!$AD$9:$AD$40)/1000000),0)))} -> 9 | F6: =IF(LARGE('Step 1 Regressions'!$AD$9:$AD$40,1)<=0,"",LARGE('Step 1 Regressions'!$AD$9:$AD$40,1)) -> 27 | G6: =IF(F6="","",IF(ABS(F6)>=20,"Dominant Luck Story",IF(ABS(F6)>=15,"Consistently Lucky",IF(ABS(F6)>=10,"Moderately Lucky","One-Model Signal")))) -> Dominant Luck Story | H6: =IF(F6="","",TRIM((IF(C6>0,"A1: "&C6&" pts. ","No A1 signal. "))&(IF(D6>0,"A2: "&D6&" pts. ","No A2 signal. "))&(IF(E6>0,"A3: "&E6&" pts.","No A3 signal.")))) -> No A1 signal. A2: 10 pts. A3: 9 pts.
A7: =IF(LARGE('Step 1 Regressions'!$AD$9:$AD$40,2)<=0,"",2) -> 2 | B7: {=IF(LARGE('Step 1 Regressions'!$AD$9:$AD$40,2)<=0,"",INDEX('Step 1 Regressions'!$B$9:$B$40,MATCH(LARGE(('Step 1 Regressions'!$AD$9:$AD$40+ROW('Step 1 Regressions'!$AD$9:$AD$40)/1000000),2),('Step 1 Regressions'!$AD$9:$AD$40+ROW('Step 1 Regressions'!$AD$9:$AD$40)/1000000),0)))} -> Boston Bruins | C7: {=IF(LARGE('Step 1 Regressions'!$AD$9:$AD$40,2)<=0,"",INDEX('Step 1 Regressions'!$T$9:$T$40,MATCH(LARGE(('Step 1 Regressions'!$AD$9:$AD$40+ROW('Step 1 Regressions'!$AD$9:$AD$40)/1000000),2),('Step 1 Regressions'!$AD$9:$AD$40+ROW('Step 1 Regressions'!$AD$9:$AD$40)/1000000),0)))} -> 0 | D7: {=IF(LARGE('Step 1 Regressions'!$AD$9:$AD$40,2)<=0,"",INDEX('Step 1 Regressions'!$U$9:$U$40,MATCH(LARGE(('Step 1 Regressions'!$AD$9:$AD$40+ROW('Step 1 Regressions'!$AD$9:$AD$40)/1000000),2),('Step 1 Regressions'!$AD$9:$AD$40+ROW('Step 1 Regressions'!$AD$9:$AD$40)/1000000),0)))} -> 9 | E7: {=IF(LARGE('Step 1 Regressions'!$AD$9:$AD$40,2)<=0,"",INDEX('Step 1 Regressions'!$V$9:$V$40,MATCH(LARGE(('Step 1 Regressions'!$AD$9:$AD$40+ROW('Step 1 Regressions'!$AD$9:$AD$40)/1000000),2),('Step 1 Regressions'!$AD$9:$AD$40+ROW('Step 1 Regressions'!$AD$9:$AD$40)/1000000),0)))} -> 10 | F7: =IF(LARGE('Step 1 Regressions'!$AD$9:$AD$40,2)<=0,"",LARGE('Step 1 Regressions'!$AD$9:$AD$40,2)) -> 25 | G7: =IF(F7="","",IF(ABS(F7)>=20,"Dominant Luck Story",IF(ABS(F7)>=15,"Consistently Lucky",IF(ABS(F7)>=10,"Moderately Lucky","One-Model Signal")))) -> Dominant Luck Story | H7: =IF(F7="","",TRIM((IF(C7>0,"A1: "&C7&" pts. ","No A1 signal. "))&(IF(D7>0,"A2: "&D7&" pts. ","No A2 signal. "))&(IF(E7>0,"A3: "&E7&" pts.","No A3 signal.")))) -> No A1 signal. A2: 9 pts. A3: 10 pts.
